<?xml version="1.0"?>
<robot xmlns:xacro="http://www.ros.org/wiki/xacro" >
    
    <xacro:include filename="inertial_macros.xacro" />

    <material name="white">
        <color rgba="1 1 1 1" />
    </material>
    
    <material name="orange">
        <color rgba="1 0.3 0.1 1" />
    </material>

    <material name="blue">
        <color rgba="0.2 0.2 1 1" />
    </material>

    <material name="black">
        <color rgba="0 0 0 1" />
    </material>

    <!-- Base Link -->

    <link name="base_link">

    </link>

    <!-- Chassis Link -->

    <joint name="chassis_joint" type="fixed">
        <parent link="base_link"/>
        <child link="chassis"/>
        <origin xyz="-0.23 0 0"/>
    </joint>

    <link name="chassis">
        <visual>
            <origin xyz="0.23 0 0.305"/>
            <geometry>
                <box size="0.46 0.285  0.61"/>
            </geometry>
            <material name="white"/>
        </visual>
        <collision>
            <origin xyz="0.23 0 0.305"/>
            <geometry>
                <box size="0.46 0.285  0.61"/>
            </geometry>
        </collision>
        <xacro:inertial_box mass="3.175" x="0.46" y="0.285" z="0.61">
            <origin xyz="0.23 0 0.305" rpy="0 0 0"/>
        </xacro:inertial_box>
    </link>

    <gazebo reference="chassis">
        <material>Gazebo/White</material>
    </gazebo>

    <!-- Left Back wheel link-->

    <joint name="left_back_wheel_joint" type="continuous">
        <parent link="base_link"/>
        <child link="left_back_wheel"/>
        <origin xyz="0 0.16 0" rpy="-${pi/2} 0 0"/>
        <axis xyz="0 0 1"/>
    </joint>

    <link name="left_back_wheel">
        <!--visual>
            <geometry>
                <cylinder radius="0.035" length="0.02"/>
            </geometry>
            <material name="blue"/>
        </visual-->
        <!--collision>
            <geometry>
                <sphere radius="0.035"/>
            </geometry>
        </collision-->
        <xacro:inertial_cylinder mass="0.2" length="0.02" radius="0.035">
            <origin xyz="0 0 0" rpy="0 0 0"/>
        </xacro:inertial_cylinder>
    </link>

    <gazebo reference="left_back_wheel">
        <material>Gazebo/Blue</material>
    </gazebo>

    <!-- Left front wheel link-->

    <joint name="left_front_wheel_joint" type="continuous">
        <parent link="base_link"/>
        <child link="left_front_wheel"/>
        <origin xyz="0.13 0.16 0" rpy="-${pi/2} 0 0"/>
        <axis xyz="0 0 1"/>
    </joint>

    <link name="left_front_wheel">
        <visual>
            <geometry>
                <cylinder radius="0.035" length="0.02"/>
            </geometry>
            <material name="blue"/>
        </visual>
        <collision>
            <geometry>
                <sphere radius="0.035"/>
            </geometry>
        </collision>
        <xacro:inertial_cylinder mass="0.2" length="0.02" radius="0.035">
            <origin xyz="0 0 0" rpy="0 0 0"/>
        </xacro:inertial_cylinder>
    </link>

    <gazebo reference="left_front_wheel">
        <material>Gazebo/Blue</material>
    </gazebo>

    <!-- Right Back wheel link-->

    <joint name="right_back_wheel_joint" type="continuous">
        <parent link="base_link"/>
        <child link="right_back_wheel"/>
        <origin xyz="0 -0.16 0" rpy="${pi/2} 0 0"/>
        <axis xyz="0 0 -1"/>
    </joint>

    <link name="right_back_wheel">
        <!--visual>
            <geometry>
                <cylinder radius="0.035" length="0.02"/>
            </geometry>
            <material name="blue"/>
        </visual-->
        <!--collision>
            <geometry>
                <sphere radius="0.035"/>
            </geometry>
        </collision-->
        <xacro:inertial_cylinder mass="0.2" length="0.02" radius="0.035">
            <origin xyz="0 0 0" rpy="0 0 0"/>
        </xacro:inertial_cylinder>
    </link>

    <gazebo reference="right_back_wheel">
        <material>Gazebo/Blue</material>
    </gazebo>

    <!-- Right front wheel link-->

    <joint name="right_front_wheel_joint" type="continuous">
        <parent link="base_link"/>
        <child link="right_front_wheel"/>
        <origin xyz="0.13 -0.16 0" rpy="${pi/2} 0 0"/>
        <axis xyz="0 0 -1"/>
    </joint>

    <link name="right_front_wheel">
        <visual>
            <geometry>
                <cylinder radius="0.035" length="0.02"/>
            </geometry>
            <material name="blue"/>
        </visual>
        <collision>
            <geometry>
                <sphere radius="0.035"/>
            </geometry>
        </collision>
        <xacro:inertial_cylinder mass="0.2" length="0.02" radius="0.035">
            <origin xyz="0 0 0" rpy="0 0 0"/>
        </xacro:inertial_cylinder>
    </link>    

    <gazebo reference="right_front_wheel">
        <material>Gazebo/Blue</material>
    </gazebo>

    <!--Left Caster wheel Link-->

    <joint name="left_caster_wheel_joint" type="fixed">
        <parent link="chassis"/>
        <child link="left_caster_wheel"/>
        <origin xyz="0.13 0.09 0"/>
    </joint>

    <link name="left_caster_wheel">
        <visual>
            <geometry>
                <sphere radius="0.035"/>
            </geometry>
            <material name="black"/>
        </visual>
        <collision>
            <geometry>
                <sphere radius="0.035"/>
            </geometry>
        </collision>
        <xacro:inertial_sphere mass="0.2" radius="0.035">
            <origin xyz="0 0 0" rpy="0 0 0"/>
        </xacro:inertial_sphere>
    </link>

    <gazebo reference="left_caster_wheel">
        <material>Gazebo/Black</material>
        <mu1 value="0.001"/>
        <mu2 value="0.001"/>
    </gazebo>

    <!--Right Caster wheel Link-->

    <joint name="right_caster_wheel_joint" type="fixed">
        <parent link="chassis"/>
        <child link="right_caster_wheel"/>
        <origin xyz="0.13 -0.09 0"/>
    </joint>

    <link name="right_caster_wheel">
        <visual>
            <geometry>
                <sphere radius="0.035"/>
            </geometry>
            <material name="black"/>
        </visual>
        <collision>
            <geometry>
                <sphere radius="0.035"/>
            </geometry>
        </collision>
        <xacro:inertial_sphere mass="0.2" radius="0.035">
            <origin xyz="0 0 0" rpy="0 0 0"/>
        </xacro:inertial_sphere>
    </link>

    <gazebo reference="right_caster_wheel">
        <material>Gazebo/Black</material>
        <mu1 value="0.001"/>
        <mu2 value="0.001"/>
    </gazebo>

</robot>